<?xml version="1.0"?>
<robot xmlns:xacro="http://www.ros.org/wiki/xacro"  >

    <xacro:include filename="inertial_macros.xacro"/>

<!--MATERIALS-->

    <material name="white">
        <color rgba="1 1 1 1" />
    </material>

    <material name="orange">
        <color rgba="1 0.3 0.1 1" />
    </material>

    <material name="blue">
        <color rgba="0.2 0.2 1 1" />
    </material>

    <material name="black">
        <color rgba="0 0 0 1" />
    </material>

<!--BASE LINK-->

    <link name="base_link">
    </link>

<!--CHASSIS LINK-->

    <joint name="chassis_joint" type="fixed">
        <parent link="base_link"/>
        <child link="chassis"/>
        <origin xyz="-0.1 0 0"/>
    </joint>

    <link name="chassis">
        <visual>
            <origin xyz="0.0825 0 0.025" rpy="0 0 0"/>
            <geometry>
                <box size="0.165 0.165 0.05"/>
            </geometry>
            <material name="white"/>
        </visual>
        <collision>
            <origin xyz="0.0825 0 0.025" rpy="0 0 0"/>
            <geometry>
                <box size="0.165 0.165 0.05"/>
            </geometry>
            <material name="white"/>
        </collision>
        <xacro:inertial_box mass="0.5" x="0.3" y="0.3" z="0.15">
            <origin xyz="0.0825 0 0.025" rpy="0 0 0"/>
        </xacro:inertial_box>
    </link>

    <gazebo reference="chassis">
        <material>Gazebo/White</material>
    </gazebo>
   
<!--BACK LEFT WHEEL LINK-->

    <joint name ="back_left_wheel_joint" type="continuous">
        <parent link="base_link"/>
        <child link="back_left_wheel"/>
        <origin xyz="0.065 0.100 0" rpy="-${pi/2} 0 0"/>
        <axis xyz="0 0 1"/>
    </joint>

    <link name="back_left_wheel">
        <visual>
            <geometry>
                <cylinder length="0.03" radius="0.03"/>
            </geometry>
            <material name="black"/>
        </visual>
        <collision>
            <geometry>
                <cylinder length="0.030" radius="0.030"/>
            </geometry>
            <material name="black"/>
        </collision>
        <xacro:inertial_cylinder mass="0.1" length="0.03" radius="0.03">
            <origin xyz="0 0 0" rpy="0 0 0"/>
        </xacro:inertial_cylinder>
    </link>

    <gazebo reference="back_left_wheel">
        <material>Gazebo/Black</material>
    </gazebo>

<!--BACK RIGHT WHEEL LINK-->

    <joint name ="back_right_wheel_joint" type="continuous">
        <parent link="base_link"/>
        <child link="back_right_wheel"/>
        <origin xyz="0.065 -0.100 0" rpy="${pi/2} 0 0"/>
        <axis xyz="0 0 -1"/>
    </joint>

    <link name="back_right_wheel">
        <visual>
            <geometry>
                <cylinder length="0.030" radius="0.030"/>
            </geometry>
            <material name ="black"/>
        </visual>
        <collision>
            <geometry>
                <cylinder length="0.030" radius="0.030"/>
            </geometry>
            <material name ="black"/>
        </collision>
        <xacro:inertial_cylinder mass="0.1" length="0.03" radius="0.03">
            <origin xyz="0 0 0" rpy="0 0 0"/>
        </xacro:inertial_cylinder>
    </link>

    <gazebo reference="back_right_wheel">
        <material>Gazebo/Black</material>
    </gazebo>

<!--FRONT LEFT WHEEL LINK-->

    <joint name ="front_left_wheel_joint" type="fixed">
        <parent link="base_link"/>
        <child link="front_left_wheel"/>
        <origin xyz="-0.075 0.100 0" rpy="-${pi/2} 0 0"/>
        <axis xyz="0 0 1"/>
    </joint>

    <link name="front_left_wheel">
        <visual>
            <geometry>
                <cylinder length="0.03" radius="0.03"/>
            </geometry>
            <material name="black"/>
        </visual>
        <collision>
            <geometry>
                <cylinder length="0.030" radius="0.030"/>
            </geometry>
            <material name="black"/>
        </collision>
        <xacro:inertial_cylinder mass="0.1" length="0.03" radius="0.03">
            <origin xyz="0 0 0" rpy="0 0 0"/>
        </xacro:inertial_cylinder>
    </link>

    <gazebo reference="front_left_wheel">
        <material>Gazebo/Black</material>
        <mu1 value="0.001"/>
        <mu2 value="0.001"/>
    </gazebo>

<!--FRONT RIGHT WHEEL LINK-->

    <joint name ="front_right_wheel_joint" type="fixed">
        <parent link="base_link"/>
        <child link="front_right_wheel"/>
        <origin xyz="-0.075 -0.100 0" rpy="${pi/2} 0 0"/>
        <axis xyz="0 0 -1"/>
    </joint>

    <link name="front_right_wheel">
        <visual>
            <geometry>
                <cylinder length="0.030" radius="0.030"/>
            </geometry>
            <material name ="black"/>
        </visual>
        <collision>
            <geometry>
                <cylinder length="0.030" radius="0.030"/>
            </geometry>
            <material name ="black"/>
        </collision>
        <xacro:inertial_cylinder mass="0.1" length="0.03" radius="0.03">
            <origin xyz="0 0 0" rpy="0 0 0"/>
        </xacro:inertial_cylinder>
    </link>

    <gazebo reference="front_right_wheel">
        <material>Gazebo/Black</material>
        <mu1 value="0.001"/>
        <mu2 value="0.001"/>
    </gazebo>

<!--MIDDLE LEFT WHEEL LINK-->

    <joint name ="middle_left_wheel_joint" type="fixed">
        <parent link="base_link"/>
        <child link="middle_left_wheel"/>
        <origin xyz="0 0.100 0" rpy="-${pi/2} 0 0"/>
        <axis xyz="0 0 1"/>
    </joint>

    <link name="middle_left_wheel">
        <visual>
            <geometry>
                <cylinder length="0.03" radius="0.03"/>
            </geometry>
            <material name="black"/>
        </visual>
        <collision>
            <geometry>
                <cylinder length="0.030" radius="0.030"/>
            </geometry>
            <material name="black"/>
        </collision>
        <xacro:inertial_cylinder mass="0.1" length="0.03" radius="0.03">
            <origin xyz="0 0 0" rpy="0 0 0"/>
        </xacro:inertial_cylinder>
    </link>

    <gazebo reference="middle_left_wheel">
        <material>Gazebo/Black</material>
        <mu1 value="0.001"/>
        <mu2 value="0.001"/>
    </gazebo>

<!--MIDDLE RIGHT WHEEL LINK-->   

    <joint name ="middle_right_wheel_joint" type="fixed">
        <parent link="base_link"/>
        <child link="middle_right_wheel"/>
        <origin xyz="0 -0.100 0" rpy="${pi/2} 0 0"/>
        <axis xyz="0 0 -1"/>
    </joint>

    <link name="middle_right_wheel">
        <visual>
            <geometry>
                <cylinder length="0.030" radius="0.030"/>
            </geometry>
            <material name ="black"/>
        </visual>
        <collision>
            <geometry>
                <cylinder length="0.030" radius="0.030"/>
            </geometry>
            <material name ="black"/>
        </collision>
        <xacro:inertial_cylinder mass="0.1" length="0.03" radius="0.03">
            <origin xyz="0 0 0" rpy="0 0 0"/>
        </xacro:inertial_cylinder>
    </link>

    <gazebo reference="middle_right_wheel">
        <material>Gazebo/Black</material>
        <mu1 value="0.001"/>
        <mu2 value="0.001"/>
    </gazebo>

</robot>